Workbook

Sheet EY Ireland PPM Planner 2025
B2: Archived Asset
A3: Site Information | B3: Site Information | C3: PM Task Generation | H3: Asset Information | I3: Task Allocation | J3: Contractor | K3: Managed By | L3: ISS Checklist (Y/N) | M3: Purchase Order | N3: 2024 Cost | O3: 2025 Cost | P3: Percentage Increase | Q3: Yearly Schedule | AC3: Comments
C4: Maintenance Plan Description | D4: Non-Stat | E4: Stat | F4: Non Stat | G4: Stat | Q4: Jan | R4: Feb | S4: Mar | T4: Apr | U4: May | V4: Jun | W4: Jul | X4: Aug | Y4: Sep | Z4: Oct | AA4: Nov | AB4: Dec
A5: Site | B5: Building | D5: Frequencies | E5: Frequencies | F5: Requires Doc | G5: Requires Doc | H5: Name | I5: Work Group | J5: Vendor | Q5: 2025 | R5: 2025 | S5: 2025 | T5: 2025 | U5: 2025 | V5: 2025 | W5: 2025 | X5: 2025 | Y5: 2025 | Z5: 2025 | AA5: 2025 | AB5: 2025
A6: Waterford | B6: The Atrium | C6: BS-R-IE002-54.03-May-1 | E6: 6M | G6: 6M | H6: 54.03:Split Systems / Heatpumps | I6: Waterford - M&E PPM's | J6: Burlington | K6: Burlington | M6: TBC | N6: 744.48 | O6: 960 | U6: 6M - Done | AA6: 6M- Done
A7: Waterford | B7: The Atrium | C7: BS-R-IE002-54.03-May-1 | H7: UK-WFTA-FL01-SHP-54.03-AC Indoor Unit Fan Coils
A8: Waterford | B8: The Atrium | C8: BS-R-IE002-54.03-May-1 | H8: UK-WFTA-FL01-SHP-54.03-AC Split Wall Cassette
A9: Waterford | B9: The Atrium | C9: BS-R-IE002-54.03-May-2 | E9: 6M | G9: 6M | H9: 54.03:Condensers Air Cooled | I9: Waterford - M&E PPM's | J9: Burlington | K9: Burlington | M9: TBC | N9: 744.48 | O9: ref line 11 | U9: 6M - Done | AA9: 6M- Done
A10: Waterford | B10: The Atrium | C10: BS-R-IE002-54.03-May-2 | H10: UK-WFTA-ROF-CAC-54.03-AC Condenser 1
A11: Waterford | B11: The Atrium | C11: BS-R-IE002-54.03-May-2 | H11: UK-WFTA-ROF-CAC-54.03-AC Condenser 2
A12: Waterford | B12: The Atrium | C12: BS-R-IE002-54.03-May-2 | H12: UK-WFTA-ROF-CAC-54.03-AC Condenser Comms Room
A13: Waterford | B13: The Atrium | C13: BS-R-IE002-95.12-Dec-1 | H13: UK-WFTA-FL01-WHE-95.12-Water Heater-002
A14: Waterford | B14: The Atrium | C14: BS-R-IE002-95.12-Dec-1 | H14: UK-WFTA-FL01-WHE-95.12-Water Heater-003
A15: Waterford | B15: The Atrium | C15: BS-R-IE002-95.12-Dec-1 | H15: UK-WFTA-FL01-WHE-95.12-Water Heater-004
A16: Waterford | B16: The Atrium | C16: BS-R-IE002-95.12-Dec-1 | H16: UK-WFTA-FL01-WHE-95.12-Water Heater-005
A17: Waterford | B17: The Atrium | C17: BS-R-IE002-95.12-Dec-1 | H17: UK-WFTA-FL01-WHE-95.12-Water Heater-007
A18: Waterford | B18: The Atrium | C18: BS-R-IE002-95.12-Dec-1 | H18: UK-WFTA-FL01-WHE-95.12-Water Heater-001
A19: Waterford | B19: The Atrium | C19: BS-R-IE002-95.12-Dec-1 | H19: UK-WFTA-FL01-WHE-95.12-Water Heater-006
A20: Waterford | B20: The Atrium | C20: BS-R-IE002-51.01-Mar-1 | E20: 3M | H20: 51.01:Showers | I20: Waterford - M&E PPM's | J20: Burlington | K20: Burlington | L20: N | M20: N/A | N20: 0 | O20: 0 | Q20: 3M | T20: 3M - Done | W20: 3M - Done | Z20: 3M - Done
A21: Waterford | B21: The Atrium | C21: BS-R-IE002-51.01-Mar-1 | H21: UK-WFTA-FL01-SHO-51.01-Shower-001
A22: Waterford | B22: The Atrium | C22: BS-R-IE002-51.01-Mar-1 | H22: UK-WFTA-FL01-SHO-51.01-Shower-002
A23: Waterford | B23: The Atrium | C23: BS-R-IE002-NONSFG:DMF-Jun-1 | D23: 12M | H23: DMF:Domestic Appliances | I23: Waterford - M&E PPM's | J23: WPC Internal | K23: ISS | L23: N | M23: N/A | N23: 0 | O23: 0 | U23: 12M
A24: Waterford | B24: The Atrium | C24: BS-R-IE002-NONSFG:DMF-Jun-1 | H24: UK-WFTA-FL01-DMF-Non SFG-Dishwasher
A25: Waterford | B25: The Atrium | C25: BS-R-IE002-NONSFG:DMF-Jun-1 | H25: UK-WFTA-FL01-DMF-97.16-Microwave
A26: Waterford | B26: The Atrium | C26: BS-R-IE002-NONSFG:DMF-Jun-1 | H26: UK-WFTA-FL01-DMF-91.03-Coffee Machine
A27: Waterford | B27: The Atrium | C27: BS-R-IE002-NONSFG:DMF-Jun-1 | H27: UK-WFTA-FL01-DMF-10.02-Fridge
A28: Waterford | B28: The Atrium | C28: BE-R-IE002-88.50-Jun-1 | E28: 12M | H28: 88.50:Mechanical Filing | I28: Waterford - M&E PPM's | J28: Masters Choice | K28: ISS | M28: TBC | N28: Never Done | O28: 1600 | U28: 12M
A29: Waterford | B29: The Atrium | C29: BE-R-IE002-88.50-Jun-1 | H29: UK-WFTA-FL03-WAP-88.50-Mechanical Filing
A30: Waterford | B30: The Atrium | C30: BS-R-IE002-95.12-Dec-1 | E30: 12M | H30: 95.12:Water Heaters Packaged Electric | I30: Waterford - M&E PPM's | J30: Burlington | K30: Burlington | M30: TBC | N30: 93.06 | O30: 480 | U30: 12M - Done
A31: Waterford | B31: The Atrium | C31: BE-R-IE002-95.12-Feb-1 | H31: UK-WFTA-FL01-DWB-95.12-Zip:Drinking Water Boiler:3rd Kitchen
A32: Waterford | B32: The Atrium | C32: BE-R-IE002-95.12-Feb-1 | H32: UK-WFTA-FL01-DWB-95.12-Zip:Drinking Water Boiler:1st Canteen
A33: Waterford | B33: The Atrium | C33: BE-R-IE002-49.02-Mar-1 | D33: 12M | H33: UK-WFTA-FL01-CTV-49.02-CCTV System | I33: Waterford - M&E PPM's | J33: Q3 | K33: ISS | N33: 713.34 | O33: 80 | R33: 12M - Done
A34: Waterford | B34: The Atrium | H34: Distribution Boards (DB's) | I34: Waterford - M&E PPM's | J34: ENG LEAD | K34: ISS | R34: 12M - Done
A35: Waterford | B35: The Atrium | C35: BE-R-IE002-14.20-Jun-1 | D35: 12M | H35: 14.20:Emergency Assistance Alarms | I35: Waterford - M&E PPM's | J35: Burlington | K35: Burlington | M35: TBC | N35: 93.06 | O35: 480 | U35: 12M
A36: Waterford | B36: The Atrium | C36: BE-R-IE002-37.01-Aug-1 | E36: 3M | G36: 12M | H36: UK-WFTA-FL01-SEC-37.01-Emergency Light | I36: Waterford - M&E PPM's | J36: ENG LEAD | K36: ISS | L36: N | M36: N/A | N36: 1310.1 | O36: 0 | Q36: 3M - Done | T36: 3M - Done | W36: 12M - Done | Z36: 3M - Done
A37: Waterford | B37: The Atrium | C37: BE-R-IE002-14.20-Jun-1 | D37: 1M | H37: 14.20:Emergency Assistance Alarms | I37: Waterford - M&E PPM's | J37: WPC Internal | K37: ISS | L37: N | M37: N/A | N37: 0 | O37: 0 | Q37: 1M - Done | R37: 1M - Done | S37: 1M - Done | T37: 1M - Done | U37: 12M - Done | V37: 1M - Done | W37: 1M - Done | X37: 1M - Done | Y37: 1M - Done | Z37: 1M - Done | AA37: 1M - Done | AB37: 1M - Done
A38: Waterford | B38: The Atrium | C38: BE-R-IE002-23.17-Jun-1 | D38: 1M | H38: UK-WFTA-FL01-FDI-23.17-Fire Doors | I38: Waterford - M&E PPM's | J38: WPC Internal | K38: ISS | L38: N | M38: N/A | N38: 0 | O38: 0 | Q38: 1M - Done | R38: 1M - Done | S38: 1M - Done | T38: 1M - Done | U38: 1M - Done | V38: 1M - Done | W38: 1M - Done | X38: 1M - Done | Y38: 1M - Done | Z38: 1M - Done | AA38: 1M - Done | AB38: 1M - Done
A39: Waterford | B39: The Atrium | C39: BE-R-IE002-23.17-Jun-1 | E39: 12M | H39: UK-WFTA-FL01-FDI-23.17-Fire Doors | I39: Waterford - M&E PPM's | J39: Burlington | K39: Burlington | M39: TBC | N39: 93.06 | O39: 480 | U39: 12M - Done
A40: Waterford | B40: The Atrium | C40: BE-R-IE002-23.09-Jun-1 | E40: 12M | G40: 12M | H40: UK-WFTA-FL01-FEC-23.09-Fire Extinguisher, CO2 | I40: Waterford - M&E PPM's | J40: G4S | K40: Burlington | N40: 613 | O40: 420 | U40: 12M - Done
A41: Waterford | B41: The Atrium | C41: BE-R-IE002-32.02-Jun-1 | E41: 1M | G41: 1M | H41: UK-WFTA-FL01-WSE-32.02-Hot & Cold Water Services | I41: Waterford - M&E PPM's | J41: WPC Internal | K41: ISS | L41: N | M41: N/A | N41: 0 | O41: 0 | Q41: 1M - Done | R41: 1M - Done | S41: 1M - Done | T41: 1M - Done | U41: 1M - Done | V41: 1M - Done | W41: 1M - Done | X41: 1M - Done | Y41: 1M - Done | Z41: 1M - Done | AA41: 1M - Done | AB41: 1M - Done
...

Sheet PPM Dashboard
A3: Building/ Site | B3: Janaury | E3: February | H3: March | K3: April | N3: May | Q3: June | T3: July | W3: August | Z3: September | AC3: October | AF3: November | AI3: December
B4: Count | C4: ACHV | D4: % | E4: Count | F4: ACHV | G4: % | H4: Count | I4: ACHV | J4: % | K4: Count | L4: ACHV | M4: % | N4: Count | O4: ACHV | P4: % | Q4: Count | R4: ACHV | S4: % | T4: Count | U4: ACHV | V4: % | W4: Count | X4: ACHV | Y4: % | Z4: Count | AA4: ACHV | AB4: % | AC4: Count | AD4: ACHV | AE4: % | AF4: Count | AG4: ACHV | AH4: % | AI4: Count | AJ4: ACHV | AK4: %
A5: Dublin - Station Building | B5: =COUNTIFS('EY Ireland PPM Planner 2025'!$B:$B,'EY Ireland PPM Planner 2025'!$B497,'EY Ireland PPM Planner 2025'!Q:Q,"<>") -> 8 | C5: =COUNTIFS('EY Ireland PPM Planner 2025'!$B:$B,'EY Ireland PPM Planner 2025'!$B497,'EY Ireland PPM Planner 2025'!Q:Q,"*Done*") -> 8 | D5: =C5/B5 -> 1 | E5: =COUNTIFS('EY Ireland PPM Planner 2025'!$B:$B, 'EY Ireland PPM Planner 2025'!$B497, 'EY Ireland PPM Planner 2025'!R:R,"<>") -> 17 | F5: =COUNTIFS('EY Ireland PPM Planner 2025'!$B:$B, 'EY Ireland PPM Planner 2025'!$B497, 'EY Ireland PPM Planner 2025'!R:R,"*Done*") -> 12 | G5: =F5/E5 -> 0.70588235 | H5: =COUNTIFS('EY Ireland PPM Planner 2025'!$B:$B, 'EY Ireland PPM Planner 2025'!$B497, 'EY Ireland PPM Planner 2025'!S:S,"<>") -> 14 | I5: =COUNTIFS('EY Ireland PPM Planner 2025'!$B:$B, 'EY Ireland PPM Planner 2025'!$B497, 'EY Ireland PPM Planner 2025'!S:S,"*Done*") -> 9 | J5: =I5/H5 -> 0.64285714 | K5: =COUNTIFS('EY Ireland PPM Planner 2025'!$B:$B, 'EY Ireland PPM Planner 2025'!$B497, 'EY Ireland PPM Planner 2025'!T:T,"<>") -> 10 | L5: =COUNTIFS('EY Ireland PPM Planner 2025'!$B:$B, 'EY Ireland PPM Planner 2025'!$B497, 'EY Ireland PPM Planner 2025'!T:T,"*Done*") -> 8 | M5: =L5/K5 -> 0.8 | N5: =COUNTIFS('EY Ireland PPM Planner 2025'!$B:$B, 'EY Ireland PPM Planner 2025'!$B497, 'EY Ireland PPM Planner 2025'!U:U,"<>") -> 13 | O5: =COUNTIFS('EY Ireland PPM Planner 2025'!$B:$B, 'EY Ireland PPM Planner 2025'!$B497, 'EY Ireland PPM Planner 2025'!U:U,"*Done*") -> 10 | P5: =O5/N5 -> 0.76923077 | Q5: =COUNTIFS('EY Ireland PPM Planner 2025'!$B:$B, 'EY Ireland PPM Planner 2025'!$B497, 'EY Ireland PPM Planner 2025'!V:V,"<>") -> 8 | R5: =COUNTIFS('EY Ireland PPM Planner 2025'!$B:$B, 'EY Ireland PPM Planner 2025'!$B497, 'EY Ireland PPM Planner 2025'!V:V,"*Done*") -> 6 | S5: =R5/Q5 -> 0.75 | T5: =COUNTIFS('EY Ireland PPM Planner 2025'!$B:$B, 'EY Ireland PPM Planner 2025'!$B497, 'EY Ireland PPM Planner 2025'!W:W,"<>") -> 13 | U5: =COUNTIFS('EY Ireland PPM Planner 2025'!$B:$B, 'EY Ireland PPM Planner 2025'!$B497, 'EY Ireland PPM Planner 2025'!W:W,"*Done*") -> 5 | V5: =U5/T5 -> 0.38461538 | W5: =COUNTIFS('EY Ireland PPM Planner 2025'!$B:$B, 'EY Ireland PPM Planner 2025'!$B497, 'EY Ireland PPM Planner 2025'!X:X,"<>") -> 20 | X5: =COUNTIFS('EY Ireland PPM Planner 2025'!$B:$B, 'EY Ireland PPM Planner 2025'!$B497, 'EY Ireland PPM Planner 2025'!X:X,"*Done*") -> 9 | Y5: =X5/W5 -> 0.45 | Z5: =COUNTIFS('EY Ireland PPM Planner 2025'!$B:$B, 'EY Ireland PPM Planner 2025'!$B497, 'EY Ireland PPM Planner 2025'!Y:Y,"<>") -> 16 | AA5: =COUNTIFS('EY Ireland PPM Planner 2025'!$B:$B, 'EY Ireland PPM Planner 2025'!$B497, 'EY Ireland PPM Planner 2025'!Y:Y,"*Done*") -> 4 | AB5: =AA5/Z5 -> 0.25 | AC5: =COUNTIFS('EY Ireland PPM Planner 2025'!$B:$B, 'EY Ireland PPM Planner 2025'!$B497, 'EY Ireland PPM Planner 2025'!Z:Z,"<>") -> 8 | AD5: =COUNTIFS('EY Ireland PPM Planner 2025'!$B:$B, 'EY Ireland PPM Planner 2025'!$B497, 'EY Ireland PPM Planner 2025'!Z:Z,"*Done*") -> 2 | AE5: =AD5/AC5 -> 0.25 | AF5: =COUNTIFS('EY Ireland PPM Planner 2025'!$B:$B, 'EY Ireland PPM Planner 2025'!$B497, 'EY Ireland PPM Planner 2025'!AA:AA,"<>") -> 10 | AG5: =COUNTIFS('EY Ireland PPM Planner 2025'!$B:$B, 'EY Ireland PPM Planner 2025'!$B497, 'EY Ireland PPM Planner 2025'!AA:AA,"*Done*") -> 3 | AH5: =AG5/AF5 -> 0.3 | AI5: =COUNTIFS('EY Ireland PPM Planner 2025'!$B:$B, 'EY Ireland PPM Planner 2025'!$B497, 'EY Ireland PPM Planner 2025'!AB:AB,"<>") -> 8 | AJ5: =COUNTIFS('EY Ireland PPM Planner 2025'!$B:$B, 'EY Ireland PPM Planner 2025'!$B497, 'EY Ireland PPM Planner 2025'!AB:AB,"*Done*") -> 1 | AK5: =AJ5/AI5 -> 0.125
A6: Dublin - Harcourt Centre | B6: =COUNTIFS('EY Ireland PPM Planner 2025'!$B:$B,'EY Ireland PPM Planner 2025'!$B136, 'EY Ireland PPM Planner 2025'!Q:Q,"<>") -> 9 | C6: =COUNTIFS('EY Ireland PPM Planner 2025'!$B:$B,'EY Ireland PPM Planner 2025'!$B136, 'EY Ireland PPM Planner 2025'!Q:Q,"*Done*") -> 9 | D6: =C6/B6 -> 1 | E6: =COUNTIFS('EY Ireland PPM Planner 2025'!$B:$B,'EY Ireland PPM Planner 2025'!$B136, 'EY Ireland PPM Planner 2025'!R:R,"<>") -> 29 | F6: =COUNTIFS('EY Ireland PPM Planner 2025'!$B:$B,'EY Ireland PPM Planner 2025'!$B136, 'EY Ireland PPM Planner 2025'!R:R,"*Done*") -> 29 | G6: =F6/E6 -> 1 | H6: =COUNTIFS('EY Ireland PPM Planner 2025'!$B:$B,'EY Ireland PPM Planner 2025'!$B136, 'EY Ireland PPM Planner 2025'!S:S,"<>") -> 12 | I6: =COUNTIFS('EY Ireland PPM Planner 2025'!$B:$B,'EY Ireland PPM Planner 2025'!$B136, 'EY Ireland PPM Planner 2025'!S:S,"*Done*") -> 11 | J6: =I6/H6 -> 0.91666667 | K6: =COUNTIFS('EY Ireland PPM Planner 2025'!$B:$B,'EY Ireland PPM Planner 2025'!$B136, 'EY Ireland PPM Planner 2025'!T:T,"<>") -> 9 | L6: =COUNTIFS('EY Ireland PPM Planner 2025'!$B:$B,'EY Ireland PPM Planner 2025'!$B136, 'EY Ireland PPM Planner 2025'!T:T,"*Done*") -> 9 | M6: =L6/K6 -> 1 | N6: =COUNTIFS('EY Ireland PPM Planner 2025'!$B:$B,'EY Ireland PPM Planner 2025'!$B136, 'EY Ireland PPM Planner 2025'!U:U,"<>") -> 15 | O6: =COUNTIFS('EY Ireland PPM Planner 2025'!$B:$B,'EY Ireland PPM Planner 2025'!$B136, 'EY Ireland PPM Planner 2025'!U:U,"*Done*") -> 15 | P6: =O6/N6 -> 1 | Q6: =COUNTIFS('EY Ireland PPM Planner 2025'!$B:$B,'EY Ireland PPM Planner 2025'!$B136, 'EY Ireland PPM Planner 2025'!V:V,"<>") -> 9 | R6: =COUNTIFS('EY Ireland PPM Planner 2025'!$B:$B,'EY Ireland PPM Planner 2025'!$B136, 'EY Ireland PPM Planner 2025'!V:V,"*Done*") -> 7 | S6: =R6/Q6 -> 0.77777778 | T6: =COUNTIFS('EY Ireland PPM Planner 2025'!$B:$B,'EY Ireland PPM Planner 2025'!$B136, 'EY Ireland PPM Planner 2025'!W:W,"<>") -> 17 | U6: =COUNTIFS('EY Ireland PPM Planner 2025'!$B:$B,'EY Ireland PPM Planner 2025'!$B136, 'EY Ireland PPM Planner 2025'!W:W,"*Done*") -> 13 | V6: =U6/T6 -> 0.76470588 | W6: =COUNTIFS('EY Ireland PPM Planner 2025'!$B:$B,'EY Ireland PPM Planner 2025'!$B136, 'EY Ireland PPM Planner 2025'!X:X,"<>") -> 33 | X6: =COUNTIFS('EY Ireland PPM Planner 2025'!$B:$B,'EY Ireland PPM Planner 2025'!$B136, 'EY Ireland PPM Planner 2025'!X:X,"*Done*") -> 24 | Y6: =X6/W6 -> 0.72727273 | Z6: =COUNTIFS('EY Ireland PPM Planner 2025'!$B:$B,'EY Ireland PPM Planner 2025'!$B136, 'EY Ireland PPM Planner 2025'!Y:Y,"<>") -> 11 | AA6: =COUNTIFS('EY Ireland PPM Planner 2025'!$B:$B,'EY Ireland PPM Planner 2025'!$B136, 'EY Ireland PPM Planner 2025'!Y:Y,"*Done*") -> 9 | AB6: =AA6/Z6 -> 0.81818182 | AC6: =COUNTIFS('EY Ireland PPM Planner 2025'!$B:$B,'EY Ireland PPM Planner 2025'!$B136, 'EY Ireland PPM Planner 2025'!Z:Z,"<>") -> 8 | AD6: =COUNTIFS('EY Ireland PPM Planner 2025'!$B:$B,'EY Ireland PPM Planner 2025'!$B136, 'EY Ireland PPM Planner 2025'!Z:Z,"*Done*") -> 3 | AE6: =AD6/AC6 -> 0.375 | AF6: =COUNTIFS('EY Ireland PPM Planner 2025'!$B:$B,'EY Ireland PPM Planner 2025'!$B136, 'EY Ireland PPM Planner 2025'!AA:AA,"<>") -> 8 | AG6: =COUNTIFS('EY Ireland PPM Planner 2025'!$B:$B,'EY Ireland PPM Planner 2025'!$B136, 'EY Ireland PPM Planner 2025'!AA:AA,"*Done*") -> 2 | AH6: =AG6/AF6 -> 0.25 | AI6: =COUNTIFS('EY Ireland PPM Planner 2025'!$B:$B,'EY Ireland PPM Planner 2025'!$B136, 'EY Ireland PPM Planner 2025'!AB:AB,"<>") -> 8 | AJ6: =COUNTIFS('EY Ireland PPM Planner 2025'!$B:$B,'EY Ireland PPM Planner 2025'!$B136, 'EY Ireland PPM Planner 2025'!AB:AB,"*Done*") -> 1 | AK6: =AJ6/AI6 -> 0.125
A7: Galway - Hibernian House | B7: =COUNTIFS('EY Ireland PPM Planner 2025'!$B:$B,'EY Ireland PPM Planner 2025'!$B597, 'EY Ireland PPM Planner 2025'!Q:Q,"<>") -> 6 | C7: =COUNTIFS('EY Ireland PPM Planner 2025'!$B:$B,'EY Ireland PPM Planner 2025'!$B597, 'EY Ireland PPM Planner 2025'!Q:Q,"*Done*") -> 6 | D7: =C7/B7 -> 1 | E7: =COUNTIFS('EY Ireland PPM Planner 2025'!$B:$B,'EY Ireland PPM Planner 2025'!$B597, 'EY Ireland PPM Planner 2025'!R:R,"<>") -> 11 | F7: =COUNTIFS('EY Ireland PPM Planner 2025'!$B:$B,'EY Ireland PPM Planner 2025'!$B597, 'EY Ireland PPM Planner 2025'!R:R,"*Done*") -> 10 | G7: =F7/E7 -> 0.90909091 | H7: =COUNTIFS('EY Ireland PPM Planner 2025'!$B:$B,'EY Ireland PPM Planner 2025'!$B597, 'EY Ireland PPM Planner 2025'!S:S,"<>") -> 4 | I7: =COUNTIFS('EY Ireland PPM Planner 2025'!$B:$B,'EY Ireland PPM Planner 2025'!$B597, 'EY Ireland PPM Planner 2025'!S:S,"*Done*") -> 4 | J7: =I7/H7 -> 1 | K7: =COUNTIFS('EY Ireland PPM Planner 2025'!$B:$B,'EY Ireland PPM Planner 2025'!$B597, 'EY Ireland PPM Planner 2025'!T:T,"<>") -> 6 | L7: =COUNTIFS('EY Ireland PPM Planner 2025'!$B:$B,'EY Ireland PPM Planner 2025'!$B597, 'EY Ireland PPM Planner 2025'!T:T,"*Done*") -> 5 | M7: =L7/K7 -> 0.83333333 | N7: =COUNTIFS('EY Ireland PPM Planner 2025'!$B:$B,'EY Ireland PPM Planner 2025'!$B597, 'EY Ireland PPM Planner 2025'!U:U,"<>") -> 10 | O7: =COUNTIFS('EY Ireland PPM Planner 2025'!$B:$B,'EY Ireland PPM Planner 2025'!$B597, 'EY Ireland PPM Planner 2025'!U:U,"*Done*") -> 9 | P7: =O7/N7 -> 0.9 | Q7: =COUNTIFS('EY Ireland PPM Planner 2025'!$B:$B,'EY Ireland PPM Planner 2025'!$B597, 'EY Ireland PPM Planner 2025'!V:V,"<>") -> 4 | R7: =COUNTIFS('EY Ireland PPM Planner 2025'!$B:$B,'EY Ireland PPM Planner 2025'!$B597, 'EY Ireland PPM Planner 2025'!V:V,"*Done*") -> 4 | S7: =R7/Q7 -> 1 | T7: =COUNTIFS('EY Ireland PPM Planner 2025'!$B:$B,'EY Ireland PPM Planner 2025'!$B597, 'EY Ireland PPM Planner 2025'!W:W,"<>") -> 9 | U7: =COUNTIFS('EY Ireland PPM Planner 2025'!$B:$B,'EY Ireland PPM Planner 2025'!$B597, 'EY Ireland PPM Planner 2025'!W:W,"*Done*") -> 6 | V7: =U7/T7 -> 0.66666667 | W7: =COUNTIFS('EY Ireland PPM Planner 2025'!$B:$B,'EY Ireland PPM Planner 2025'!$B597, 'EY Ireland PPM Planner 2025'!X:X,"<>") -> 10 | X7: =COUNTIFS('EY Ireland PPM Planner 2025'!$B:$B,'EY Ireland PPM Planner 2025'!$B597, 'EY Ireland PPM Planner 2025'!X:X,"*Done*") -> 7 | Y7: =X7/W7 -> 0.7 | Z7: =COUNTIFS('EY Ireland PPM Planner 2025'!$B:$B,'EY Ireland PPM Planner 2025'!$B597, 'EY Ireland PPM Planner 2025'!Y:Y,"<>") -> 4 | AA7: =COUNTIFS('EY Ireland PPM Planner 2025'!$B:$B,'EY Ireland PPM Planner 2025'!$B597, 'EY Ireland PPM Planner 2025'!Y:Y,"*Done*") -> 4 | AB7: =AA7/Z7 -> 1 | AC7: =COUNTIFS('EY Ireland PPM Planner 2025'!$B:$B,'EY Ireland PPM Planner 2025'!$B597, 'EY Ireland PPM Planner 2025'!Z:Z,"<>") -> 6 | AD7: =COUNTIFS('EY Ireland PPM Planner 2025'!$B:$B,'EY Ireland PPM Planner 2025'!$B597, 'EY Ireland PPM Planner 2025'!Z:Z,"*Done*") -> 6 | AE7: =AD7/AC7 -> 1 | AF7: =COUNTIFS('EY Ireland PPM Planner 2025'!$B:$B,'EY Ireland PPM Planner 2025'!$B597, 'EY Ireland PPM Planner 2025'!AA:AA,"<>") -> 5 | AG7: =COUNTIFS('EY Ireland PPM Planner 2025'!$B:$B,'EY Ireland PPM Planner 2025'!$B597, 'EY Ireland PPM Planner 2025'!AA:AA,"*Done*") -> 4 | AH7: =AG7/AF7 -> 0.8 | AI7: =COUNTIFS('EY Ireland PPM Planner 2025'!$B:$B,'EY Ireland PPM Planner 2025'!$B597, 'EY Ireland PPM Planner 2025'!AB:AB,"<>") -> 4 | AJ7: =COUNTIFS('EY Ireland PPM Planner 2025'!$B:$B,'EY Ireland PPM Planner 2025'!$B597, 'EY Ireland PPM Planner 2025'!AB:AB,"*Done*") -> 4 | AK7: =AJ7/AI7 -> 1
A8: Waterford - The Atrium | B8: =COUNTIFS('EY Ireland PPM Planner 2025'!$B:$B,'EY Ireland PPM Planner 2025'!$B37, 'EY Ireland PPM Planner 2025'!Q:Q,"<>") -> 9 | C8: =COUNTIFS('EY Ireland PPM Planner 2025'!$B:$B,'EY Ireland PPM Planner 2025'!$B37, 'EY Ireland PPM Planner 2025'!Q:Q,"*Done*") -> 8 | D8: =C8/B8 -> 0.88888889 | E8: =COUNTIFS('EY Ireland PPM Planner 2025'!$B:$B,'EY Ireland PPM Planner 2025'!$B37, 'EY Ireland PPM Planner 2025'!R:R,"<>") -> 13 | F8: =COUNTIFS('EY Ireland PPM Planner 2025'!$B:$B,'EY Ireland PPM Planner 2025'!$B37, 'EY Ireland PPM Planner 2025'!R:R,"*Done*") -> 13 | G8: =F8/E8 -> 1 | H8: =COUNTIFS('EY Ireland PPM Planner 2025'!$B:$B,'EY Ireland PPM Planner 2025'!$B37, 'EY Ireland PPM Planner 2025'!S:S,"<>") -> 9 | I8: =COUNTIFS('EY Ireland PPM Planner 2025'!$B:$B,'EY Ireland PPM Planner 2025'!$B37, 'EY Ireland PPM Planner 2025'!S:S,"*Done*") -> 8 | J8: =I8/H8 -> 0.88888889 | K8: =COUNTIFS('EY Ireland PPM Planner 2025'!$B:$B,'EY Ireland PPM Planner 2025'!$B37, 'EY Ireland PPM Planner 2025'!T:T,"<>") -> 8 | L8: =COUNTIFS('EY Ireland PPM Planner 2025'!$B:$B,'EY Ireland PPM Planner 2025'!$B37, 'EY Ireland PPM Planner 2025'!T:T,"*Done*") -> 8 | M8: =L8/K8 -> 1 | N8: =COUNTIFS('EY Ireland PPM Planner 2025'!$B:$B,'EY Ireland PPM Planner 2025'!$B37, 'EY Ireland PPM Planner 2025'!U:U,"<>") -> 15 | O8: =COUNTIFS('EY Ireland PPM Planner 2025'!$B:$B,'EY Ireland PPM Planner 2025'!$B37, 'EY Ireland PPM Planner 2025'!U:U,"*Done*") -> 11 | P8: =O8/N8 -> 0.73333333 | Q8: =COUNTIFS('EY Ireland PPM Planner 2025'!$B:$B,'EY Ireland PPM Planner 2025'!$B37, 'EY Ireland PPM Planner 2025'!V:V,"<>") -> 6 | R8: =COUNTIFS('EY Ireland PPM Planner 2025'!$B:$B,'EY Ireland PPM Planner 2025'!$B37, 'EY Ireland PPM Planner 2025'!V:V,"*Done*") -> 6 | S8: =R8/Q8 -> 1 | T8: =COUNTIFS('EY Ireland PPM Planner 2025'!$B:$B,'EY Ireland PPM Planner 2025'!$B37, 'EY Ireland PPM Planner 2025'!W:W,"<>") -> 9 | U8: =COUNTIFS('EY Ireland PPM Planner 2025'!$B:$B,'EY Ireland PPM Planner 2025'!$B37, 'EY Ireland PPM Planner 2025'!W:W,"*Done*") -> 9 | V8: =U8/T8 -> 1 | W8: =COUNTIFS('EY Ireland PPM Planner 2025'!$B:$B,'EY Ireland PPM Planner 2025'!$B37, 'EY Ireland PPM Planner 2025'!X:X,"<>") -> 11 | X8: =COUNTIFS('EY Ireland PPM Planner 2025'!$B:$B,'EY Ireland PPM Planner 2025'!$B37, 'EY Ireland PPM Planner 2025'!X:X,"*Done*") -> 11 | Y8: =X8/W8 -> 1 | Z8: =COUNTIFS('EY Ireland PPM Planner 2025'!$B:$B,'EY Ireland PPM Planner 2025'!$B37, 'EY Ireland PPM Planner 2025'!Y:Y,"<>") -> 7 | AA8: =COUNTIFS('EY Ireland PPM Planner 2025'!$B:$B,'EY Ireland PPM Planner 2025'!$B37, 'EY Ireland PPM Planner 2025'!Y:Y,"*Done*") -> 7 | AB8: =AA8/Z8 -> 1 | AC8: =COUNTIFS('EY Ireland PPM Planner 2025'!$B:$B,'EY Ireland PPM Planner 2025'!$B37, 'EY Ireland PPM Planner 2025'!Z:Z,"<>") -> 8 | AD8: =COUNTIFS('EY Ireland PPM Planner 2025'!$B:$B,'EY Ireland PPM Planner 2025'!$B37, 'EY Ireland PPM Planner 2025'!Z:Z,"*Done*") -> 8 | AE8: =AD8/AC8 -> 1 | AF8: =COUNTIFS('EY Ireland PPM Planner 2025'!$B:$B,'EY Ireland PPM Planner 2025'!$B37, 'EY Ireland PPM Planner 2025'!AA:AA,"<>") -> 8 | AG8: =COUNTIFS('EY Ireland PPM Planner 2025'!$B:$B,'EY Ireland PPM Planner 2025'!$B37, 'EY Ireland PPM Planner 2025'!AA:AA,"*Done*") -> 8 | AH8: =AG8/AF8 -> 1 | AI8: =COUNTIFS('EY Ireland PPM Planner 2025'!$B:$B,'EY Ireland PPM Planner 2025'!$B37, 'EY Ireland PPM Planner 2025'!AB:AB,"<>") -> 6 | AJ8: =COUNTIFS('EY Ireland PPM Planner 2025'!$B:$B,'EY Ireland PPM Planner 2025'!$B37, 'EY Ireland PPM Planner 2025'!AB:AB,"*Done*") -> 6 | AK8: =AJ8/AI8 -> 1
A9: Cork - City Quarter | B9: =COUNTIFS('EY Ireland PPM Planner 2025'!$B:$B,'EY Ireland PPM Planner 2025'!$B82, 'EY Ireland PPM Planner 2025'!Q:Q,"<>") -> 5 | C9: =COUNTIFS('EY Ireland PPM Planner 2025'!$B:$B,'EY Ireland PPM Planner 2025'!$B82, 'EY Ireland PPM Planner 2025'!Q:Q,"*Done*") -> 5 | D9: =C9/B9 -> 1 | E9: =COUNTIFS('EY Ireland PPM Planner 2025'!$B:$B,'EY Ireland PPM Planner 2025'!$B82, 'EY Ireland PPM Planner 2025'!R:R,"<>") -> 13 | F9: =COUNTIFS('EY Ireland PPM Planner 2025'!$B:$B,'EY Ireland PPM Planner 2025'!$B82, 'EY Ireland PPM Planner 2025'!R:R,"*Done*") -> 13 | G9: =F9/E9 -> 1 | H9: =COUNTIFS('EY Ireland PPM Planner 2025'!$B:$B,'EY Ireland PPM Planner 2025'!$B82, 'EY Ireland PPM Planner 2025'!S:S,"<>") -> 3 | I9: =COUNTIFS('EY Ireland PPM Planner 2025'!$B:$B,'EY Ireland PPM Planner 2025'!$B82, 'EY Ireland PPM Planner 2025'!S:S,"*Done*") -> 3 | J9: =I9/H9 -> 1 | K9: =COUNTIFS('EY Ireland PPM Planner 2025'!$B:$B,'EY Ireland PPM Planner 2025'!$B82, 'EY Ireland PPM Planner 2025'!T:T,"<>") -> 5 | L9: =COUNTIFS('EY Ireland PPM Planner 2025'!$B:$B,'EY Ireland PPM Planner 2025'!$B82, 'EY Ireland PPM Planner 2025'!T:T,"*Done*") -> 4 | M9: =L9/K9 -> 0.8 | N9: =COUNTIFS('EY Ireland PPM Planner 2025'!$B:$B,'EY Ireland PPM Planner 2025'!$B82, 'EY Ireland PPM Planner 2025'!U:U,"<>") -> 10 | O9: =COUNTIFS('EY Ireland PPM Planner 2025'!$B:$B,'EY Ireland PPM Planner 2025'!$B82, 'EY Ireland PPM Planner 2025'!U:U,"*Done*") -> 10 | P9: =O9/N9 -> 1 | Q9: =COUNTIFS('EY Ireland PPM Planner 2025'!$B:$B,'EY Ireland PPM Planner 2025'!$B82, 'EY Ireland PPM Planner 2025'!V:V,"<>") -> 3 | R9: =COUNTIFS('EY Ireland PPM Planner 2025'!$B:$B,'EY Ireland PPM Planner 2025'!$B82, 'EY Ireland PPM Planner 2025'!V:V,"*Done*") -> 3 | S9: =R9/Q9 -> 1 | T9: =COUNTIFS('EY Ireland PPM Planner 2025'!$B:$B,'EY Ireland PPM Planner 2025'!$B82, 'EY Ireland PPM Planner 2025'!W:W,"<>") -> 5 | U9: =COUNTIFS('EY Ireland PPM Planner 2025'!$B:$B,'EY Ireland PPM Planner 2025'!$B82, 'EY Ireland PPM Planner 2025'!W:W,"*Done*") -> 4 | V9: =U9/T9 -> 0.8 | W9: =COUNTIFS('EY Ireland PPM Planner 2025'!$B:$B,'EY Ireland PPM Planner 2025'!$B82, 'EY Ireland PPM Planner 2025'!X:X,"<>") -> 16 | X9: =COUNTIFS('EY Ireland PPM Planner 2025'!$B:$B,'EY Ireland PPM Planner 2025'!$B82, 'EY Ireland PPM Planner 2025'!X:X,"*Done*") -> 13 | Y9: =X9/W9 -> 0.8125 | Z9: =COUNTIFS('EY Ireland PPM Planner 2025'!$B:$B,'EY Ireland PPM Planner 2025'!$B82, 'EY Ireland PPM Planner 2025'!Y:Y,"<>") -> 3 | AA9: =COUNTIFS('EY Ireland PPM Planner 2025'!$B:$B,'EY Ireland PPM Planner 2025'!$B82, 'EY Ireland PPM Planner 2025'!Y:Y,"*Done*") -> 3 | AB9: =AA9/Z9 -> 1 | AC9: =COUNTIFS('EY Ireland PPM Planner 2025'!$B:$B,'EY Ireland PPM Planner 2025'!$B82, 'EY Ireland PPM Planner 2025'!Z:Z,"<>") -> 5 | AD9: =COUNTIFS('EY Ireland PPM Planner 2025'!$B:$B,'EY Ireland PPM Planner 2025'!$B82, 'EY Ireland PPM Planner 2025'!Z:Z,"*Done*") -> 4 | AE9: =AD9/AC9 -> 0.8 | AF9: =COUNTIFS('EY Ireland PPM Planner 2025'!$B:$B,'EY Ireland PPM Planner 2025'!$B82, 'EY Ireland PPM Planner 2025'!AA:AA,"<>") -> 4 | AG9: =COUNTIFS('EY Ireland PPM Planner 2025'!$B:$B,'EY Ireland PPM Planner 2025'!$B82, 'EY Ireland PPM Planner 2025'!AA:AA,"*Done*") -> 4 | AH9: =AG9/AF9 -> 1 | AI9: =COUNTIFS('EY Ireland PPM Planner 2025'!$B:$B,'EY Ireland PPM Planner 2025'!$B82, 'EY Ireland PPM Planner 2025'!AB:AB,"<>") -> 3 | AJ9: =COUNTIFS('EY Ireland PPM Planner 2025'!$B:$B,'EY Ireland PPM Planner 2025'!$B82, 'EY Ireland PPM Planner 2025'!AB:AB,"*Done*") -> 3 | AK9: =AJ9/AI9 -> 1
A10: Limerick - Riverview House | B10: =COUNTIFS('EY Ireland PPM Planner 2025'!$B:$B,'EY Ireland PPM Planner 2025'!$B649, 'EY Ireland PPM Planner 2025'!Q:Q,"<>") -> 13 | C10: =COUNTIFS('EY Ireland PPM Planner 2025'!$B:$B,'EY Ireland PPM Planner 2025'!$B639, 'EY Ireland PPM Planner 2025'!Q:Q,"*Done*") -> 12 | D10: =C10/B10 -> 0.92307692 | E10: =COUNTIFS('EY Ireland PPM Planner 2025'!$B:$B,'EY Ireland PPM Planner 2025'!$B649, 'EY Ireland PPM Planner 2025'!R:R,"<>") -> 11 | F10: =COUNTIFS('EY Ireland PPM Planner 2025'!$B:$B,'EY Ireland PPM Planner 2025'!$B649, 'EY Ireland PPM Planner 2025'!R:R,"*Done*") -> 10 | G10: =F10/E10 -> 0.90909091 | H10: =COUNTIFS('EY Ireland PPM Planner 2025'!$B:$B,'EY Ireland PPM Planner 2025'!$B649, 'EY Ireland PPM Planner 2025'!S:S,"<>") -> 10 | I10: =COUNTIFS('EY Ireland PPM Planner 2025'!$B:$B,'EY Ireland PPM Planner 2025'!$B649, 'EY Ireland PPM Planner 2025'!S:S,"*Done*") -> 9 | J10: =I10/H10 -> 0.9 | K10: =COUNTIFS('EY Ireland PPM Planner 2025'!$B:$B,'EY Ireland PPM Planner 2025'!$B649, 'EY Ireland PPM Planner 2025'!T:T,"<>") -> 18 | L10: =COUNTIFS('EY Ireland PPM Planner 2025'!$B:$B,'EY Ireland PPM Planner 2025'!$B649, 'EY Ireland PPM Planner 2025'!T:T,"*Done*") -> 12 | M10: =L10/K10 -> 0.66666667 | N10: =COUNTIFS('EY Ireland PPM Planner 2025'!$B:$B,'EY Ireland PPM Planner 2025'!$B649, 'EY Ireland PPM Planner 2025'!U:U,"<>") -> 13 | O10: =COUNTIFS('EY Ireland PPM Planner 2025'!$B:$B,'EY Ireland PPM Planner 2025'!$B649, 'EY Ireland PPM Planner 2025'!U:U,"*Done*") -> 10 | P10: =O10/N10 -> 0.76923077 | Q10: =COUNTIFS('EY Ireland PPM Planner 2025'!$B:$B,'EY Ireland PPM Planner 2025'!$B649, 'EY Ireland PPM Planner 2025'!V:V,"<>") -> 11 | R10: =COUNTIFS('EY Ireland PPM Planner 2025'!$B:$B,'EY Ireland PPM Planner 2025'!$B649, 'EY Ireland PPM Planner 2025'!V:V,"*Done*") -> 9 | S10: =R10/Q10 -> 0.81818182 | T10: =COUNTIFS('EY Ireland PPM Planner 2025'!$B:$B,'EY Ireland PPM Planner 2025'!$B649, 'EY Ireland PPM Planner 2025'!W:W,"<>") -> 11 | U10: =COUNTIFS('EY Ireland PPM Planner 2025'!$B:$B,'EY Ireland PPM Planner 2025'!$B649, 'EY Ireland PPM Planner 2025'!W:W,"*Done*") -> 11 | V10: =U10/T10 -> 1 | W10: =COUNTIFS('EY Ireland PPM Planner 2025'!$B:$B,'EY Ireland PPM Planner 2025'!$B649, 'EY Ireland PPM Planner 2025'!X:X,"<>") -> 11 | X10: =COUNTIFS('EY Ireland PPM Planner 2025'!$B:$B,'EY Ireland PPM Planner 2025'!$B649, 'EY Ireland PPM Planner 2025'!X:X,"*Done*") -> 9 | Y10: =X10/W10 -> 0.81818182 | Z10: =COUNTIFS('EY Ireland PPM Planner 2025'!$B:$B,'EY Ireland PPM Planner 2025'!$B649, 'EY Ireland PPM Planner 2025'!Y:Y,"<>") -> 9 | AA10: =COUNTIFS('EY Ireland PPM Planner 2025'!$B:$B,'EY Ireland PPM Planner 2025'!$B649, 'EY Ireland PPM Planner 2025'!Y:Y,"*Done*") -> 7 | AB10: =AA10/Z10 -> 0.77777778 | AC10: =COUNTIFS('EY Ireland PPM Planner 2025'!$B:$B,'EY Ireland PPM Planner 2025'!$B649, 'EY Ireland PPM Planner 2025'!Z:Z,"<>") -> 10 | AD10: =COUNTIFS('EY Ireland PPM Planner 2025'!$B:$B,'EY Ireland PPM Planner 2025'!$B649, 'EY Ireland PPM Planner 2025'!Z:Z,"*Done*") -> 8 | AE10: =AD10/AC10 -> 0.8 | AF10: =COUNTIFS('EY Ireland PPM Planner 2025'!$B:$B,'EY Ireland PPM Planner 2025'!$B649, 'EY Ireland PPM Planner 2025'!AA:AA,"<>") -> 6 | AG10: =COUNTIFS('EY Ireland PPM Planner 2025'!$B:$B,'EY Ireland PPM Planner 2025'!$B649, 'EY Ireland PPM Planner 2025'!AA:AA,"*Done*") -> 6 | AH10: =AG10/AF10 -> 1 | AI10: =COUNTIFS('EY Ireland PPM Planner 2025'!$B:$B,'EY Ireland PPM Planner 2025'!$B649, 'EY Ireland PPM Planner 2025'!AB:AB,"<>") -> 8 | AJ10: =COUNTIFS('EY Ireland PPM Planner 2025'!$B:$B,'EY Ireland PPM Planner 2025'!$B649, 'EY Ireland PPM Planner 2025'!AB:AB,"*Done*") -> 7 | AK10: =AJ10/AI10 -> 0.875
A11: Total | B11: =SUM(B5:B10) -> 50 | C11: =SUM(C5:C10) -> 48 | D11: =C11/B11 -> 0.96 | E11: =SUM(E5:E10) -> 94 | F11: =SUM(F5:F10) -> 87 | G11: =F11/E11 -> 0.92553191 | H11: =SUM(H5:H10) -> 52 | I11: =SUM(I5:I10) -> 44 | J11: =I11/H11 -> 0.84615385 | K11: =SUM(K5:K10) -> 56 | L11: =SUM(L5:L10) -> 46 | M11: =L11/K11 -> 0.82142857 | N11: =SUM(N5:N10) -> 76 | O11: =SUM(O5:O10) -> 65 | P11: =O11/N11 -> 0.85526316 | Q11: =SUM(Q5:Q10) -> 41 | R11: =SUM(R5:R10) -> 35 | S11: =R11/Q11 -> 0.85365854 | T11: =SUM(T5:T10) -> 64 | U11: =SUM(U5:U10) -> 48 | V11: =U11/T11 -> 0.75 | W11: =SUM(W5:W10) -> 101 | X11: =SUM(X5:X10) -> 73 | Y11: =X11/W11 -> 0.72277228 | Z11: =SUM(Z5:Z10) -> 50 | AA11: =SUM(AA5:AA10) -> 34 | AB11: =AA11/Z11 -> 0.68 | AC11: =SUM(AC5:AC10) -> 45 | AD11: =SUM(AD5:AD10) -> 31 | AE11: =AD11/AC11 -> 0.68888889 | AF11: =SUM(AF5:AF10) -> 41 | AG11: =SUM(AG5:AG10) -> 27 | AH11: =AG11/AF11 -> 0.65853659 | AI11: =SUM(AI5:AI10) -> 37 | AJ11: =SUM(AJ5:AJ10) -> 22 | AK11: =AJ11/AI11 -> 0.59459459
A14: Month | B14: % ACHV
A15: January | B15: =D11 -> 0.96
A16: February | B16: =G11 -> 0.92553191
A17: March | B17: =J11 -> 0.84615385
A18: April | B18: =M11 -> 0.82142857
A19: May | B19: =P11 -> 0.85526316
A20: June | B20: =S11 -> 0.85365854
A21: July | B21: =V11 -> 0.75
A22: August | B22: =Y11 -> 0.72277228
A23: September | B23: =AB11 -> 0.68
A24: October | B24: =AE11 -> 0.68888889
A25: November | B25: =AH11 -> 0.65853659
A26: December | B26: =AK11 -> 0.59459459
A31: Percentage Completion | B31: =AVERAGE(B15:P26) -> 0.7797357

Sheet BEL Costs as of Jan 2025
A2: Dublin | I2: Cork
A4: Service | B4: Current Supplier | C4: New Supplier | D4: Visit Frequency | E4: Costs | I4: Service | J4: Current Supplier | K4: New Supplier | L4: Visit Frequency | M4: Costs
A5: 14.22:Distribution Boards (DB's) | B5: ISS TECH SERVICES | C5: BEL | D5: 12 | E5: 3240 | I5: 14.22:Distribution Boards (DB's) | J5: ISS Tech Services | K5: BEL | L5: 12 | M5: Removed
A6: 44.12:Busbar Systems | B6: ISS TECH SERVICES | C6: BEL | D6: 12 | E6: 1020 | I6: 20.08:Extract Fans | J6: ISS Tech Services | K6: BEL | L6: 6 | M6: 960
A7: 14.24:Underfloor Water Detection System | B7: DUB TECH | C7: BEL | D7: 6 | E7: 960 | I7: 54.03:Split Systems / Heatpumps | J7: ISS Tech Services | K7: BEL | L7: 6 | M7: 960
A8: 14.15:Inverters / Speed Controllers | B8: GLOBOSERV | C8: BEL | D8: 12 | E8: 240 | I8: 54.03:Condensers Air Cooled | J8: ISS Tech Services | K8: BEL | L8: 6 | M8: 240
A9: 03.01:Air Handling Units | B9: GLOBOSERV | C9: BEL | D9: 6 | E9: 2400 | I9: 95.12:Water Heaters Packaged Electric | J9: ISS Tech Services | K9: BEL | L9: 12 | M9: 120
A10: 54.03:Split Systems / Heatpumps 001 | B10: GLOBOSERV | C10: BEL | D10: 6 | E10: 2400 | I10: 88.50:Walls and partitions Incl Sliding / Mobile | K10: Masterchoice | L10: 12 | M10: 3312
A11: 54.03:Condensers Air Cooled | B11: GLOBOSERV | C11: BEL | D11: 6 | E11: 13200 | I11: 95.12:Zip Drinking Water Boiler | K11: ZIP | M11: Removed
A12: 54.03:Condensate Pump | B12: GLOBOSERV | C12: BEL | D12: 6 | E12: 0 | I12: BMS | K12: Ashdown | M12: 750
A13: 32.07:Calorifier Hot Water Supply | B13: DGM | C13: BEL | D13: 6 | E13: 960 | I13: Access Control | K13: NA | M13: Removed
A14: 95.12:Water Heaters Packaged Electric | B14: DUB TECH | C14: BEL | D14: 12 | E14: 300 | I14: Hot & Cold Water Services | K14: ESI | M14: 2100
A15: 29.03:Plate Recuperator | B15: GLOBOSERV | C15: BEL | D15: 6 | E15: 240 | I15: Leak Detection System | K15: G4S | M15: 634
A16: 54.03:Split Systems / Heatpumps 002 | B16: GLOBOSERV | C16: BEL | D16: 6 | E16: 1560 | I16: Fire Doors | K16: BEL | M16: 520
A17: 54.03:Split Systems / Heatpumps 003 | B17: GLOBOSERV | C17: BEL | D17: 6 | E17: 1560 | I17: Emergency Light | K17: BEL | L17: 3 | M17: Removed
A18: 37.01:Emergency Lighting | B18: ISS TECH SERVICES | C18: BEL | D18: 3 | E18: 1920 | I18: Ducting including Fire Dampers | K18: NA | M18: Not included
A19: 14.22:Distribution Boards (DB's) SB | B19: ISS TECH SERVICES | C19: BEL | D19: 12 | E19: 360 | I19: Fan Coils | K19: BEL | L19: 6 | M19: 3060
A20: 14.22:Control Panels(Electrical Services) SB | B20: ISS TECH SERVICES | C20: BEL | D20: 12 | E20: 960 | I20: Fire Extinguisher, Foam | K20: G4S | M20: 585
A21: 03.01:Air Handling Units SB | B21: GLOBOSERV | C21: BEL | D21: 6 | E21: 1440 | I21: Fire Extinguishers CO2 | K21: G4S
A22: 54.03:Split Systems / Heatpumps SB | B22: GLOBOSERV | C22: BEL | D22: 6 | E22: 0 | I22: Total | M22: =SUM(M5:M21) -> 13241
A23: 54.03:Condensers Air Cooled SB | B23: GLOBOSERV | C23: BEL | D23: 6 | E23: 480
A24: 45.01:Circulating Pump SB | B24: DGM | C24: BEL | D24: 6 | E24: 480 | I24: Galway
A25: 32.12:Expansion Vessels SB | B25: DGM | C25: BEL | D25: 6 | E25: 480
A26: 56.02:Tanks CWS SB | B26: HBE | C26: BEL | D26: 12 | E26: 120 | I26: Service | J26: Current Supplier | K26: New Supplier | L26: Visit Frequency | M26: Costs
A27: 95.12:Water Heaters Packaged Electric SB | B27: ISS TECH SERVICES | C27: BEL | D27: 12 | E27: 120 | I27: 14.22:Distribution Boards (DB's) | J27: ISS Tech Services | K27: BEL | L27: 12 | M27: Removed
A28: 51.01:Showers SB | B28: ISS TECH SERVICES | C28: BEL | D28: 3 | E28: 1200 | I28: 54.03:Split Systems / Heatpumps | J28: ISS Tech Services | K28: BEL | L28: 6 | M28: 1680
A29: 05.23:Boiler SB | B29: DGM | C29: BEL | D29: 6 | E29: 960 | I29: 54.03:Condensers Air Cooled | J29: ISS Tech Services | K29: BEL | L29: 6
A30: 22.01:Fire Alarm System | B30: FSI | C30: Good Fire & Safety | D30: 3 | E30: 2300 | I30: Zip:Drinking Water Boiler:1st Floor | K30: Zip | L30: 12 | M30: Removed
A31: 23.13:Fire Extinguishers Water | B31: AMBER FIRE | C31: G4S | D31: 12 | E31: 2551 | I31: Valves & Pipework - CWS & HWS | K31: BEL | L31: 12 | M31: 480
A32: 87.06:Fire Blankets | B32: FSI | C32: G4S | D32: 12 | I32: Heat Recovery Unit | K32: BEL | L32: 6 | M32: 480
A33: 23.16:Kitchen Hood Fire Suppression | B33: AMBER FIRE | C33: G4S | D33: 6 | E33: 1799 | I33: Emergency Light | K33: BEL | L33: 3 | M33: Removed
A34: 71.06:Grease / Oil Separators (Greasheild) | B34: DRAIN DOCTOR | C34: FM environmental | D34: 3 | E34: 1456 | I34: Fire Doors | K34: BEL | L34: 12 | M34: 520
A35: 20.08:Extract Fans (cleaning) | B35: ENVRO HYGIENE | C35: Airways | D35: 6 | E35: 2125 | I35: Hot & Cold Water Services | K35: ESI | M35: 1200
A36: 06.05:BMS Outstations | B36: ASHDOWN CONTROLS | C36: Ashdown Controls | D36: 6 | E36: 1500 | I36: Security Access System | K36: NA | M36: Removed
A37: 14.19:Access Systems (Door Access Control) | B37: M&J Electronics | C37: NA | D37: 6 | E37: Removed | I37: Access System | K37: NA | M37: Removed
A38: 95.12:Drinking Water Boiler | B38: ZIP TAP | C38: NA | D38: 6 | E38: Removed | I38: CCTV | K38: NA | M38: Removed
A39: 88.50:Walls and Partitions | B39: Masters Choice | C39: Master Choice | D39: 12 | E39: 3312 | I39: Water Filter | K39: BEL | M39: 550
A40: 65.10:Water Treatment Chemical Dosing SB | B40: HBE | C40: ESI | D40: 12 | E40: 3500 | I40: Fire Extinguisher, CO2 | K40: G4S | M40: 288
A41: 95.12:Drinking Water Boiler | B41: ZIP TAP | C41: NA | D41: 6 | E41: Removed | I41: Fire Extinguisher, Foam | K41: G4S
A42: 14.20:Emergency Assistance Alarms/leak detection SB | B42: ISS TECH SERVICES | C42: Good Fire & Safety | D42: 12 | E42: 480 | I42: Extractor (not duct cleaning) | K42: BEL | M42: 480
...

Sheet Costing CCN 2025 Service Stream
A1: Costing Service Stream | B1: SubCategory | C1: Description | D1: Supplier | E1: Managed By | F1: Cost 2024 | G1: Cost 2025
A3: WS1 | F3: 281,
A4: WS2 | B4: Cleaning Services | C4: Cleaning Staff / Deep Cleans and Periodic Cleans including waste management services | D4: ISS | E4: ISS | F4: 441315.2
A6: WS3 | B6: Food Services | C6: Applied to Labour Only. Hopitality and Free Issues are adhoc | D6: ISS | E6: ISS | F6: 281792.32
A7: WS4 | B7: Office Services | C7: Staffing Costs for Dublin and Regional WPC Team | D7: ISS | E7: ISS | F7: 540411.66
A8: WS5 | B8: Security Services | C8: Including Manguarding, CCTV, Access Control, Patrol/Response and Intruder Alarm
A9: WPM | B9: Management Services | C9: WPM, Account Management (IT, H&S, KAM, Burden) | D9: ISS | E9: ISS | F9: 126854.97
